2020-05-24 19:57:30,834 ERROR: Exception on /detect_mask/f2cad8e943778cc.jpg [GET] [in c:\users\zheng\anaconda3\envs\yolo\lib\site-packages\flask\app.py:1892]
Traceback (most recent call last):
  File "c:\users\zheng\anaconda3\envs\yolo\lib\site-packages\flask\app.py", line 2447, in wsgi_app
    response = self.full_dispatch_request()
  File "c:\users\zheng\anaconda3\envs\yolo\lib\site-packages\flask\app.py", line 1952, in full_dispatch_request
    rv = self.handle_user_exception(e)
  File "c:\users\zheng\anaconda3\envs\yolo\lib\site-packages\flask\app.py", line 1821, in handle_user_exception
    reraise(exc_type, exc_value, tb)
  File "c:\users\zheng\anaconda3\envs\yolo\lib\site-packages\flask\_compat.py", line 39, in reraise
    raise value
  File "c:\users\zheng\anaconda3\envs\yolo\lib\site-packages\flask\app.py", line 1950, in full_dispatch_request
    rv = self.dispatch_request()
  File "c:\users\zheng\anaconda3\envs\yolo\lib\site-packages\flask\app.py", line 1936, in dispatch_request
    return self.view_functions[rule.endpoint](**req.view_args)
  File "c:\users\zheng\anaconda3\envs\yolo\lib\site-packages\flask_login\utils.py", line 272, in decorated_view
    return func(*args, **kwargs)
  File "C:\Users\ZHENG\Desktop\microblog\app\routes.py", line 176, in detect_image_mask
    ax, image, result = mask_rcnn.detect_image(photos.path(filename))
  File "D:/yolo/Mask_RCNN-master\mask_rcnn.py", line 91, in detect_image
    model._make_predict_function()
AttributeError: 'MaskRCNN' object has no attribute '_make_predict_function'
2020-05-24 19:59:29,021 INFO: Microblog startup [in C:\Users\ZHENG\Desktop\microblog\app\__init__.py:43]
2020-05-24 19:59:58,729 ERROR: Exception on /detect_mask/15822f5e47f86fd.jpg [GET] [in c:\users\zheng\anaconda3\envs\yolo\lib\site-packages\flask\app.py:1892]
Traceback (most recent call last):
  File "c:\users\zheng\anaconda3\envs\yolo\lib\site-packages\flask\app.py", line 2447, in wsgi_app
    response = self.full_dispatch_request()
  File "c:\users\zheng\anaconda3\envs\yolo\lib\site-packages\flask\app.py", line 1952, in full_dispatch_request
    rv = self.handle_user_exception(e)
  File "c:\users\zheng\anaconda3\envs\yolo\lib\site-packages\flask\app.py", line 1821, in handle_user_exception
    reraise(exc_type, exc_value, tb)
  File "c:\users\zheng\anaconda3\envs\yolo\lib\site-packages\flask\_compat.py", line 39, in reraise
    raise value
  File "c:\users\zheng\anaconda3\envs\yolo\lib\site-packages\flask\app.py", line 1950, in full_dispatch_request
    rv = self.dispatch_request()
  File "c:\users\zheng\anaconda3\envs\yolo\lib\site-packages\flask\app.py", line 1936, in dispatch_request
    return self.view_functions[rule.endpoint](**req.view_args)
  File "c:\users\zheng\anaconda3\envs\yolo\lib\site-packages\flask_login\utils.py", line 272, in decorated_view
    return func(*args, **kwargs)
  File "C:\Users\ZHENG\Desktop\microblog\app\routes.py", line 177, in detect_image_mask
    ax.imshow(image.astype(np.uint8))
NameError: name 'np' is not defined
2020-05-24 20:00:35,638 INFO: Microblog startup [in C:\Users\ZHENG\Desktop\microblog\app\__init__.py:43]
2020-05-24 20:01:02,455 ERROR: Exception on /detect_mask/15822f5e47f86fd.jpg [GET] [in c:\users\zheng\anaconda3\envs\yolo\lib\site-packages\flask\app.py:1892]
Traceback (most recent call last):
  File "c:\users\zheng\anaconda3\envs\yolo\lib\site-packages\flask\app.py", line 2447, in wsgi_app
    response = self.full_dispatch_request()
  File "c:\users\zheng\anaconda3\envs\yolo\lib\site-packages\flask\app.py", line 1952, in full_dispatch_request
    rv = self.handle_user_exception(e)
  File "c:\users\zheng\anaconda3\envs\yolo\lib\site-packages\flask\app.py", line 1821, in handle_user_exception
    reraise(exc_type, exc_value, tb)
  File "c:\users\zheng\anaconda3\envs\yolo\lib\site-packages\flask\_compat.py", line 39, in reraise
    raise value
  File "c:\users\zheng\anaconda3\envs\yolo\lib\site-packages\flask\app.py", line 1950, in full_dispatch_request
    rv = self.dispatch_request()
  File "c:\users\zheng\anaconda3\envs\yolo\lib\site-packages\flask\app.py", line 1936, in dispatch_request
    return self.view_functions[rule.endpoint](**req.view_args)
  File "c:\users\zheng\anaconda3\envs\yolo\lib\site-packages\flask_login\utils.py", line 272, in decorated_view
    return func(*args, **kwargs)
  File "C:\Users\ZHENG\Desktop\microblog\app\routes.py", line 179, in detect_image_mask
    plt.show()
NameError: name 'plt' is not defined
2020-05-24 20:01:27,920 INFO: Microblog startup [in C:\Users\ZHENG\Desktop\microblog\app\__init__.py:43]
2020-05-24 20:14:51,635 ERROR: Exception on /detect_mask/15822f5e47f86fd.jpg [GET] [in c:\users\zheng\anaconda3\envs\yolo\lib\site-packages\flask\app.py:1892]
Traceback (most recent call last):
  File "c:\users\zheng\anaconda3\envs\yolo\lib\site-packages\flask\app.py", line 2447, in wsgi_app
    response = self.full_dispatch_request()
  File "c:\users\zheng\anaconda3\envs\yolo\lib\site-packages\flask\app.py", line 1952, in full_dispatch_request
    rv = self.handle_user_exception(e)
  File "c:\users\zheng\anaconda3\envs\yolo\lib\site-packages\flask\app.py", line 1821, in handle_user_exception
    reraise(exc_type, exc_value, tb)
  File "c:\users\zheng\anaconda3\envs\yolo\lib\site-packages\flask\_compat.py", line 39, in reraise
    raise value
  File "c:\users\zheng\anaconda3\envs\yolo\lib\site-packages\flask\app.py", line 1950, in full_dispatch_request
    rv = self.dispatch_request()
  File "c:\users\zheng\anaconda3\envs\yolo\lib\site-packages\flask\app.py", line 1936, in dispatch_request
    return self.view_functions[rule.endpoint](**req.view_args)
  File "c:\users\zheng\anaconda3\envs\yolo\lib\site-packages\flask_login\utils.py", line 272, in decorated_view
    return func(*args, **kwargs)
  File "C:\Users\ZHENG\Desktop\microblog\app\routes.py", line 180, in detect_image_mask
    plt.show()
  File "c:\users\zheng\anaconda3\envs\yolo\lib\site-packages\matplotlib\pyplot.py", line 269, in show
    return _show(*args, **kw)
  File "c:\users\zheng\anaconda3\envs\yolo\lib\site-packages\matplotlib\cbook\deprecation.py", line 413, in wrapper
    return func(*args, **kwargs)
  File "c:\users\zheng\anaconda3\envs\yolo\lib\site-packages\matplotlib\backend_bases.py", line 3291, in show
    manager.canvas.figure.show()
  File "c:\users\zheng\anaconda3\envs\yolo\lib\site-packages\matplotlib\figure.py", line 442, in show
    manager.show()
  File "c:\users\zheng\anaconda3\envs\yolo\lib\site-packages\matplotlib\backends\_backend_tk.py", line 547, in show
    self.canvas._tkcanvas.bind("<Destroy>", destroy)
  File "c:\users\zheng\anaconda3\envs\yolo\lib\tkinter\__init__.py", line 1251, in bind
    return self._bind(('bind', self._w), sequence, func, add)
  File "c:\users\zheng\anaconda3\envs\yolo\lib\tkinter\__init__.py", line 1201, in _bind
    needcleanup)
  File "c:\users\zheng\anaconda3\envs\yolo\lib\tkinter\__init__.py", line 1372, in _register
    self.tk.createcommand(name, f)
RuntimeError: main thread is not in main loop
2020-05-24 20:15:19,313 ERROR: Exception on /detect_mask/f2cad8e943778cc.jpg [GET] [in c:\users\zheng\anaconda3\envs\yolo\lib\site-packages\flask\app.py:1892]
Traceback (most recent call last):
  File "c:\users\zheng\anaconda3\envs\yolo\lib\site-packages\flask\app.py", line 2447, in wsgi_app
    response = self.full_dispatch_request()
  File "c:\users\zheng\anaconda3\envs\yolo\lib\site-packages\flask\app.py", line 1952, in full_dispatch_request
    rv = self.handle_user_exception(e)
  File "c:\users\zheng\anaconda3\envs\yolo\lib\site-packages\flask\app.py", line 1821, in handle_user_exception
    reraise(exc_type, exc_value, tb)
  File "c:\users\zheng\anaconda3\envs\yolo\lib\site-packages\flask\_compat.py", line 39, in reraise
    raise value
  File "c:\users\zheng\anaconda3\envs\yolo\lib\site-packages\flask\app.py", line 1950, in full_dispatch_request
    rv = self.dispatch_request()
  File "c:\users\zheng\anaconda3\envs\yolo\lib\site-packages\flask\app.py", line 1936, in dispatch_request
    return self.view_functions[rule.endpoint](**req.view_args)
  File "c:\users\zheng\anaconda3\envs\yolo\lib\site-packages\flask_login\utils.py", line 272, in decorated_view
    return func(*args, **kwargs)
  File "C:\Users\ZHENG\Desktop\microblog\app\routes.py", line 180, in detect_image_mask
    plt.show()
  File "c:\users\zheng\anaconda3\envs\yolo\lib\site-packages\matplotlib\pyplot.py", line 269, in show
    return _show(*args, **kw)
  File "c:\users\zheng\anaconda3\envs\yolo\lib\site-packages\matplotlib\cbook\deprecation.py", line 413, in wrapper
    return func(*args, **kwargs)
  File "c:\users\zheng\anaconda3\envs\yolo\lib\site-packages\matplotlib\backend_bases.py", line 3291, in show
    manager.canvas.figure.show()
  File "c:\users\zheng\anaconda3\envs\yolo\lib\site-packages\matplotlib\figure.py", line 442, in show
    manager.show()
  File "c:\users\zheng\anaconda3\envs\yolo\lib\site-packages\matplotlib\backends\_backend_tk.py", line 547, in show
    self.canvas._tkcanvas.bind("<Destroy>", destroy)
  File "c:\users\zheng\anaconda3\envs\yolo\lib\tkinter\__init__.py", line 1251, in bind
    return self._bind(('bind', self._w), sequence, func, add)
  File "c:\users\zheng\anaconda3\envs\yolo\lib\tkinter\__init__.py", line 1201, in _bind
    needcleanup)
  File "c:\users\zheng\anaconda3\envs\yolo\lib\tkinter\__init__.py", line 1372, in _register
    self.tk.createcommand(name, f)
RuntimeError: main thread is not in main loop
2020-05-24 20:15:54,845 INFO: Microblog startup [in C:\Users\ZHENG\Desktop\microblog\app\__init__.py:43]
