2020-05-25 12:38:12,257 ERROR: Exception on /detect_mask/f2cad8e943778cc.jpg [GET] [in c:\users\zheng\anaconda3\envs\yolo\lib\site-packages\flask\app.py:1892]
Traceback (most recent call last):
  File "c:\users\zheng\anaconda3\envs\yolo\lib\site-packages\flask\app.py", line 2447, in wsgi_app
    response = self.full_dispatch_request()
  File "c:\users\zheng\anaconda3\envs\yolo\lib\site-packages\flask\app.py", line 1952, in full_dispatch_request
    rv = self.handle_user_exception(e)
  File "c:\users\zheng\anaconda3\envs\yolo\lib\site-packages\flask\app.py", line 1821, in handle_user_exception
    reraise(exc_type, exc_value, tb)
  File "c:\users\zheng\anaconda3\envs\yolo\lib\site-packages\flask\_compat.py", line 39, in reraise
    raise value
  File "c:\users\zheng\anaconda3\envs\yolo\lib\site-packages\flask\app.py", line 1950, in full_dispatch_request
    rv = self.dispatch_request()
  File "c:\users\zheng\anaconda3\envs\yolo\lib\site-packages\flask\app.py", line 1936, in dispatch_request
    return self.view_functions[rule.endpoint](**req.view_args)
  File "c:\users\zheng\anaconda3\envs\yolo\lib\site-packages\flask_login\utils.py", line 272, in decorated_view
    return func(*args, **kwargs)
  File "C:\Users\ZHENG\Desktop\microblog\app\routes.py", line 180, in detect_image_mask
    plt.show()
  File "c:\users\zheng\anaconda3\envs\yolo\lib\site-packages\matplotlib\pyplot.py", line 269, in show
    return _show(*args, **kw)
  File "c:\users\zheng\anaconda3\envs\yolo\lib\site-packages\matplotlib\cbook\deprecation.py", line 413, in wrapper
    return func(*args, **kwargs)
  File "c:\users\zheng\anaconda3\envs\yolo\lib\site-packages\matplotlib\backend_bases.py", line 3291, in show
    manager.canvas.figure.show()
  File "c:\users\zheng\anaconda3\envs\yolo\lib\site-packages\matplotlib\figure.py", line 442, in show
    manager.show()
  File "c:\users\zheng\anaconda3\envs\yolo\lib\site-packages\matplotlib\backends\_backend_tk.py", line 552, in show
    self.canvas.manager.window.attributes('-topmost', 1)
  File "c:\users\zheng\anaconda3\envs\yolo\lib\tkinter\__init__.py", line 1788, in wm_attributes
    return self.tk.call(args)
RuntimeError: main thread is not in main loop
2020-05-25 12:39:17,025 ERROR: Exception on /detect_mask/15822f5e47f86fd.jpg [GET] [in c:\users\zheng\anaconda3\envs\yolo\lib\site-packages\flask\app.py:1892]
Traceback (most recent call last):
  File "c:\users\zheng\anaconda3\envs\yolo\lib\site-packages\flask\app.py", line 2447, in wsgi_app
    response = self.full_dispatch_request()
  File "c:\users\zheng\anaconda3\envs\yolo\lib\site-packages\flask\app.py", line 1952, in full_dispatch_request
    rv = self.handle_user_exception(e)
  File "c:\users\zheng\anaconda3\envs\yolo\lib\site-packages\flask\app.py", line 1821, in handle_user_exception
    reraise(exc_type, exc_value, tb)
  File "c:\users\zheng\anaconda3\envs\yolo\lib\site-packages\flask\_compat.py", line 39, in reraise
    raise value
  File "c:\users\zheng\anaconda3\envs\yolo\lib\site-packages\flask\app.py", line 1950, in full_dispatch_request
    rv = self.dispatch_request()
  File "c:\users\zheng\anaconda3\envs\yolo\lib\site-packages\flask\app.py", line 1936, in dispatch_request
    return self.view_functions[rule.endpoint](**req.view_args)
  File "c:\users\zheng\anaconda3\envs\yolo\lib\site-packages\flask_login\utils.py", line 272, in decorated_view
    return func(*args, **kwargs)
  File "C:\Users\ZHENG\Desktop\microblog\app\routes.py", line 184, in detect_image_mask
    plt.savefig(filepath, bbox_inches='tight')
  File "c:\users\zheng\anaconda3\envs\yolo\lib\site-packages\matplotlib\pyplot.py", line 723, in savefig
    fig.canvas.draw_idle()   # need this if 'transparent=True' to reset colors
  File "c:\users\zheng\anaconda3\envs\yolo\lib\site-packages\matplotlib\backends\_backend_tk.py", line 342, in draw_idle
    self._idle_callback = self._tkcanvas.after_idle(idle_draw)
  File "c:\users\zheng\anaconda3\envs\yolo\lib\tkinter\__init__.py", line 764, in after_idle
    return self.after('idle', func, *args)
  File "c:\users\zheng\anaconda3\envs\yolo\lib\tkinter\__init__.py", line 756, in after
    name = self._register(callit)
  File "c:\users\zheng\anaconda3\envs\yolo\lib\tkinter\__init__.py", line 1372, in _register
    self.tk.createcommand(name, f)
RuntimeError: main thread is not in main loop
2020-05-25 12:46:09,934 INFO: Microblog startup [in C:\Users\ZHENG\Desktop\microblog\app\__init__.py:43]
2020-06-01 13:23:19,125 INFO: Microblog startup [in C:\Users\ZHENG\Desktop\microblog\app\__init__.py:43]
2020-06-01 13:23:40,597 INFO: Microblog startup [in C:\Users\ZHENG\Desktop\microblog\app\__init__.py:43]
2020-06-01 13:24:13,204 ERROR: Exception on /detect_mask/15822f5e47f86fd.jpg [GET] [in c:\users\zheng\anaconda3\envs\yolo\lib\site-packages\flask\app.py:1892]
Traceback (most recent call last):
  File "c:\users\zheng\anaconda3\envs\yolo\lib\site-packages\flask\app.py", line 2447, in wsgi_app
    response = self.full_dispatch_request()
  File "c:\users\zheng\anaconda3\envs\yolo\lib\site-packages\flask\app.py", line 1952, in full_dispatch_request
    rv = self.handle_user_exception(e)
  File "c:\users\zheng\anaconda3\envs\yolo\lib\site-packages\flask\app.py", line 1821, in handle_user_exception
    reraise(exc_type, exc_value, tb)
  File "c:\users\zheng\anaconda3\envs\yolo\lib\site-packages\flask\_compat.py", line 39, in reraise
    raise value
  File "c:\users\zheng\anaconda3\envs\yolo\lib\site-packages\flask\app.py", line 1950, in full_dispatch_request
    rv = self.dispatch_request()
  File "c:\users\zheng\anaconda3\envs\yolo\lib\site-packages\flask\app.py", line 1936, in dispatch_request
    return self.view_functions[rule.endpoint](**req.view_args)
  File "c:\users\zheng\anaconda3\envs\yolo\lib\site-packages\flask_login\utils.py", line 272, in decorated_view
    return func(*args, **kwargs)
  File "C:\Users\ZHENG\Desktop\microblog\app\routes.py", line 179, in detect_image_mask
    ax, image, result = m.detect_image(photos.path(filename))
  File "D:/yolo/Mask_RCNN-master\mask_rcnn.py", line 98, in detect_image
    results = model.detect([image], verbose=1)
NameError: name 'model' is not defined
2020-06-01 13:25:01,402 INFO: Microblog startup [in C:\Users\ZHENG\Desktop\microblog\app\__init__.py:43]
2020-06-01 13:58:14,846 INFO: Microblog startup [in C:\Users\ZHENG\Desktop\microblog\app\__init__.py:43]
2020-06-02 09:41:00,082 ERROR: Exception on /detect_mask/15822f5e47f86fd.jpg [GET] [in c:\users\zheng\anaconda3\envs\yolo\lib\site-packages\flask\app.py:1892]
Traceback (most recent call last):
  File "c:\users\zheng\anaconda3\envs\yolo\lib\site-packages\flask\app.py", line 2447, in wsgi_app
    response = self.full_dispatch_request()
  File "c:\users\zheng\anaconda3\envs\yolo\lib\site-packages\flask\app.py", line 1952, in full_dispatch_request
    rv = self.handle_user_exception(e)
  File "c:\users\zheng\anaconda3\envs\yolo\lib\site-packages\flask\app.py", line 1821, in handle_user_exception
    reraise(exc_type, exc_value, tb)
  File "c:\users\zheng\anaconda3\envs\yolo\lib\site-packages\flask\_compat.py", line 39, in reraise
    raise value
  File "c:\users\zheng\anaconda3\envs\yolo\lib\site-packages\flask\app.py", line 1950, in full_dispatch_request
    rv = self.dispatch_request()
  File "c:\users\zheng\anaconda3\envs\yolo\lib\site-packages\flask\app.py", line 1936, in dispatch_request
    return self.view_functions[rule.endpoint](**req.view_args)
  File "c:\users\zheng\anaconda3\envs\yolo\lib\site-packages\flask_login\utils.py", line 272, in decorated_view
    return func(*args, **kwargs)
  File "C:\Users\ZHENG\Desktop\microblog\app\routes.py", line 182, in detect_image_mask
    filename = filename.split('.')[0] + '_mask_detected.jpg'
  File "c:\users\zheng\anaconda3\envs\yolo\lib\site-packages\matplotlib\pyplot.py", line 269, in show
    return _show(*args, **kw)
  File "c:\users\zheng\anaconda3\envs\yolo\lib\site-packages\matplotlib\cbook\deprecation.py", line 413, in wrapper
    return func(*args, **kwargs)
  File "c:\users\zheng\anaconda3\envs\yolo\lib\site-packages\matplotlib\backend_bases.py", line 3291, in show
    manager.canvas.figure.show()
  File "c:\users\zheng\anaconda3\envs\yolo\lib\site-packages\matplotlib\figure.py", line 442, in show
    manager.show()
  File "c:\users\zheng\anaconda3\envs\yolo\lib\site-packages\matplotlib\backends\_backend_tk.py", line 547, in show
    self.canvas._tkcanvas.bind("<Destroy>", destroy)
  File "c:\users\zheng\anaconda3\envs\yolo\lib\tkinter\__init__.py", line 1251, in bind
    return self._bind(('bind', self._w), sequence, func, add)
  File "c:\users\zheng\anaconda3\envs\yolo\lib\tkinter\__init__.py", line 1201, in _bind
    needcleanup)
  File "c:\users\zheng\anaconda3\envs\yolo\lib\tkinter\__init__.py", line 1372, in _register
    self.tk.createcommand(name, f)
RuntimeError: main thread is not in main loop
2020-06-02 09:41:18,422 INFO: Microblog startup [in C:\Users\ZHENG\Desktop\microblog\app\__init__.py:43]
